<?xml version="1.0" ?>
<!-- =================================================================================== -->
<!-- |    This document was autogenerated by xacro from /local_data/sjoshi/camera_workspace/workspace/src/catkin/robots/robot_properties/robot_properties_manipulator/xacro/manipulator.urdf.xacro | -->
<!-- |    EDITING THIS FILE BY HAND IS NOT RECOMMENDED                                 | -->
<!-- =================================================================================== -->
<!--

THIS FILE IS DEPRECATED!

It only remains for legacy support but may be deleted anytime in the future
without warning!

Use instead finger_with_stage.urdf.xacro which defines the same setup (finger
robot with stage) but defines frames in a more standard way and is a bit more
nicely organized.

-->
<robot name="manipulator" xmlns:controller="http://playerstage.sourceforge.net/gazebo/xmlschema/#controller" xmlns:interface="http://playerstage.sourceforge.net/gazebo/xmlschema/#interface" xmlns:sensor="http://playerstage.sourceforge.net/gazebo/xmlschema/#sensor" xmlns:xacro="http://playerstage.sourceforge.net/gazebo/xmlschema/#interface">
  <!-- base link -->
  <link name="base_link">
    <visual>
      <origin rpy="0 0 0" xyz="0 0 0"/>
      <geometry>
        <mesh filename="package://robot_properties_manipulator/meshes/stl/BL_Finger_Holder_SIM.stl"/>
      </geometry>
      <material name="material">
        <color rgba="0.6 0.6 1.0 1.0"/>
      </material>
    </visual>
    <collision>
      <origin rpy="0 0 0" xyz="0 0 0"/>
      <geometry>
        <mesh filename="package://robot_properties_manipulator/meshes/stl/BL_Finger_Holder_SIM.stl"/>
      </geometry>
      <material name="material">
        <color rgba="0.6 0.6 1.0 1.0"/>
      </material>
    </collision>
  </link>
  <link name="base_module_link">
    <visual>
      <origin rpy="0 0 0" xyz="0 0 0"/>
      <geometry>
        <mesh filename="package://robot_properties_manipulator/meshes/stl/SIM__BL-Finger_Base.stl"/>
      </geometry>
      <material name="material">
        <color rgba="0.6 0.6 1.0 1.0"/>
      </material>
    </visual>
    <collision>
      <origin rpy="0 0 0" xyz="0 0 0"/>
      <geometry>
        <mesh filename="package://robot_properties_manipulator/meshes/stl/SIM__BL-Finger_Base.stl"/>
      </geometry>
      <material name="material">
        <color rgba="0.6 0.6 1.0 1.0"/>
      </material>
    </collision>
  </link>
  <link name="base_stage_link">
    <visual>
      <origin rpy="0 0 0" xyz="0 0 0"/>
      <geometry>
        <mesh filename="package://robot_properties_manipulator/meshes/stl/Stage_simplified.stl"/>
      </geometry>
      <material name="material">
        <color rgba="0.6 0.6 1.0 1.0"/>
      </material>
    </visual>
    <collision>
      <origin rpy="0 0 0" xyz="0 0 0"/>
      <geometry>
        <mesh filename="package://robot_properties_manipulator/meshes/stl/Stage_simplified.stl"/>
      </geometry>
      <material name="material">
        <color rgba="0.6 0.6 1.0 1.0"/>
      </material>
    </collision>
  </link>
  <joint name="base_to_stage" type="fixed">
    <parent link="base_link"/>
    <child link="base_stage_link"/>
    <origin xyz="0 0 -0.2665"/>
  </joint>
  <joint name="base_to_module" type="fixed">
    <parent link="base_link"/>
    <child link="base_module_link"/>
    <origin xyz="0 0.20595 0"/>
  </joint>
  <!-- proximal link -->
  <link name="proximal_link">
    <visual>
      <origin rpy="0 0 0" xyz="0 0 0"/>
      <geometry>
        <mesh filename="package://robot_properties_manipulator/meshes/stl/SIM__BL-Finger_Proximal.stl"/>
      </geometry>
      <material name="material">
        <color rgba="0.6 0.6 1.0 1.0"/>
      </material>
    </visual>
    <collision>
      <origin rpy="0 0 0" xyz="0 0 0"/>
      <geometry>
        <mesh filename="package://robot_properties_manipulator/meshes/stl/SIM__BL-Finger_Proximal.stl"/>
      </geometry>
      <material name="material">
        <color rgba="0.6 0.6 1.0 1.0"/>
      </material>
    </collision>
    <inertial>
      <origin rpy="0 0 0" xyz="0 0.06 0"/>
      <mass value="0.2"/>
      <inertia ixx="0.000333333333333" ixy="0" ixz="0" iyy="1.33333333333e-05" iyz="0" izz="0.000333333333333"/>
    </inertial>
  </link>
  <!-- central link -->
  <link name="central_link">
    <visual>
      <origin rpy="0 0 0" xyz="0 0 0"/>
      <geometry>
        <mesh filename="package://robot_properties_manipulator/meshes/stl/SIM__BL-Finger_Intermediate.stl"/>
      </geometry>
      <material name="material">
        <color rgba="0.6 0.6 1.0 1.0"/>
      </material>
    </visual>
    <collision>
      <origin rpy="0 0 0" xyz="0 0 0"/>
      <geometry>
        <mesh filename="package://robot_properties_manipulator/meshes/stl/SIM__BL-Finger_Intermediate.stl"/>
      </geometry>
      <material name="material">
        <color rgba="0.6 0.6 1.0 1.0"/>
      </material>
    </collision>
    <inertial>
      <origin rpy="0 0 0" xyz="0 -0.06 0"/>
      <mass value="0.2"/>
      <inertia ixx="0.000333333333333" ixy="0" ixz="0" iyy="1.33333333333e-05" iyz="0" izz="0.000333333333333"/>
    </inertial>
  </link>
  <!-- distal link -->
  <link name="distal_link">
    <visual>
      <origin rpy="0 0 0" xyz="0 0 0"/>
      <geometry>
        <mesh filename="package://robot_properties_manipulator/meshes/stl/SIM_BL_FINGER_TIP_LINK.stl"/>
      </geometry>
      <material name="material">
        <color rgba="0.6 0.6 1.0 1.0"/>
      </material>
    </visual>
    <collision>
      <origin rpy="0 0 0" xyz="0 0 0"/>
      <geometry>
        <mesh filename="package://robot_properties_manipulator/meshes/stl/SIM_BL_FINGER_TIP_LINK.stl"/>
      </geometry>
      <material name="material">
        <color rgba="0.6 0.6 1.0 1.0"/>
      </material>
    </collision>
    <inertial>
      <origin rpy="0 0 0" xyz="0 -0.07 0"/>
      <mass value="0.05"/>
      <inertia ixx="8.20833333333e-05" ixy="0" ixz="0" iyy="8.33333333333e-07" iyz="0" izz="8.20833333333e-05"/>
    </inertial>
  </link>
  <link name="distal_padding_link">
    <visual>
      <origin rpy="0 0 0" xyz="0 0 0"/>
      <geometry>
        <mesh filename="package://robot_properties_manipulator/meshes/stl/finger_padding.stl"/>
      </geometry>
      <material name="material">
        <color rgba="0.6 0.6 1.0 1.0"/>
      </material>
    </visual>
    <collision>
      <origin rpy="0 0 0" xyz="0 0 0"/>
      <geometry>
        <mesh filename="package://robot_properties_manipulator/meshes/stl/finger_padding.stl"/>
      </geometry>
      <material name="material">
        <color rgba="0.6 0.6 1.0 1.0"/>
      </material>
    </collision>
  </link>
  <joint name="tip_to_padding" type="fixed">
    <parent link="distal_link"/>
    <child link="distal_padding_link"/>
    <origin xyz="-0.0125 -0.16 0"/>
  </joint>
  <!-- kinematics -->
  <joint name="base_proximal_joint" type="revolute">
    <parent link="base_link"/>
    <child link="proximal_link"/>
    <limit effort="1000" lower="0" upper="3.14" velocity="1000"/>
    <axis rpy="0 0 0" xyz="0 1 0"/>
    <origin rpy="0 -1.5708 0" xyz="0 0 0"/>
  </joint>
  <joint name="proximal_central_joint" type="revolute">
    <parent link="proximal_link"/>
    <child link="central_link"/>
    <limit effort="1000" lower="-5.846853" upper="0" velocity="1000"/>
    <axis rpy="0 0 0" xyz="-1 0 0"/>
    <origin rpy="2.9234265 0 0" xyz="0.014 0.02695 0"/>
  </joint>
  <joint name="central_distal_joint" type="revolute">
    <parent link="central_link"/>
    <child link="distal_link"/>
    <limit effort="1000" lower="0" upper="6.00394" velocity="1000"/>
    <axis rpy="0 0 0" xyz="1 0 0"/>
    <origin rpy="-2.9 0 0" xyz="0 -0.16 0"/>
  </joint>
</robot>
